<?xml version="1.0" ?>
<robot name="turtlebot3_burger"
  xmlns:xacro="http://ros.org/wiki/xacro">
  <!-- <xacro:include filename="$(find turtlebot3_description)/urdf/common_properties.urdf"/> -->

  <!-- Init colour -->
  <material name="black">
      <color rgba="0.0 0.0 0.0 1.0"/>
  </material>

  <material name="dark">
    <color rgba="0.3 0.3 0.3 1.0"/>
  </material>

  <material name="light_black">
    <color rgba="0.4 0.4 0.4 1.0"/>
  </material>

  <material name="blue">
    <color rgba="0.0 0.0 0.8 1.0"/>
  </material>

  <material name="green">
    <color rgba="0.0 0.8 0.0 1.0"/>
  </material>

  <material name="grey">
    <color rgba="0.5 0.5 0.5 1.0"/>
  </material>

  <material name="orange">
    <color rgba="1.0 0.4235 0.0392 1.0"/>
  </material>

  <material name="brown">
    <color rgba="0.8706 0.8118 0.7647 1.0"/>
  </material>

  <material name="red">
    <color rgba="0.8 0.0 0.0 1.0"/>
  </material>

  <material name="white">
    <color rgba="1.0 1.0 1.0 1.0"/>
  </material>

  <link name="myrobot1/base_footprint"/>

  <joint name="myrobot1/base_joint" type="fixed">
    <parent link="myrobot1/base_footprint"/>
    <child link="myrobot1/base_link"/>
    <origin xyz="0.0 0.0 0.010" rpy="0 0 0"/>
  </joint>

  <link name="myrobot1/base_link">
    <visual>
      <origin xyz="-0.032 0 0.0" rpy="0 0 0"/>
      <geometry>
        <mesh filename="package://turtlebot3_gazebo/models/turtlebot3_common/meshes/burger_base.dae" scale="0.001 0.001 0.001"/>
      </geometry>
      <material name="light_black"/>
    </visual>

    <collision>
      <origin xyz="-0.032 0 0.070" rpy="0 0 0"/>
      <geometry>
        <box size="0.140 0.140 0.143"/>
      </geometry>
    </collision>

    <inertial>
      <origin xyz="0 0 0" rpy="0 0 0"/>
      <mass value="8.2573504e-01"/>
      <inertia ixx="2.2124416e-03" ixy="-1.2294101e-05" ixz="3.4938785e-05" iyy="2.1193702e-03" iyz="-5.0120904e-06" izz="2.0064271e-03" />
    </inertial>
  </link>

  <joint name="myrobot1/flag_joint" type="revolute">
    <axis xyz="0 -1 0"/>
    <origin rpy="0 0 0" xyz="0.025 -0.05 0.14"/>
    <limit effort="1000.0" lower="0.0" upper="1.57" velocity="0.5"/>
    <parent link="myrobot1/base_link"/>
    <child link="myrobot1/flag"/>
  </joint>

  <link name="myrobot1/flag">
    <visual>
      <origin rpy="0.0 0 0" xyz="0.05 0 0"/>
      <geometry>
        <box size="0.1 0.02 0.02"/>
      </geometry>
    </visual>
    <collision>
        <geometry>
            <box size="0.1 0.02 0.02"/>
        </geometry>
        <origin rpy="0.0 0 0" xyz="0 0 0"/>
    </collision>
    <inertial>
        <mass value="0.05"/>
        <inertia ixx="1e-3" ixy="0.0" ixz="0.0" iyy="1e-3" iyz="0.0" izz="1e-3" />
    </inertial>
  </link>

  <link name="myrobot1/camera_link">
    <visual>
      <origin xyz="0.0 0 0.0" rpy="0 0 0" />
      <geometry>
        <box size="0.017 0.03 0.03" />
      </geometry>
    </visual>

    <!-- Inertial properties should ideally be specified here -->
    <inertial>
      <origin xyz="0 0 0" />
      <mass value="0.1" />
      <inertia ixx="0.0001" iyy="0.0001" izz="0.0001" ixy="0" ixz="0" iyz="0" />
    </inertial>
  </link>

  <joint name="myrobot1/camera_joint" type="fixed">
    <parent link="myrobot1/base_link" />
    <child link="myrobot1camera_link" />
    <origin xyz="0.05 0.0 0.14" rpy="0 0 0" />
  </joint>

  <joint name="myrobot1/camera_optical_joint" type="fixed">
    <origin xyz="0 0 0" rpy="-1.57 0 -1.57"/>
    <parent link="myrobot1/camera_link"/>
    <child link= "camera_link_optical"/>
  </joint>

  <link name="myrobot1/camera_link_optical"/>

  <gazebo reference="camera_link">
    <sensor type="camera" name="camera">
      <update_rate>30.0</update_rate>
      <camera>
        <horizontal_fov>0.93</horizontal_fov>
        <image>
          <width>320</width>
          <height>240</height>
          <format>R8G8B8</format>
        </image>
        <clip>
          <near>0.05</near>
          <far>8.0</far>
        </clip>
      </camera>
      <noise>
        <type>gaussian</type>
        <mean>0.0</mean>
        <stddev>0.007</stddev>
      </noise>
    </sensor>
    <plugin name="camera_controller" filename="libgazebo_ros_camera.so">
      <frame_name>camera_link_optical</frame_name>
      <cameraName>camera</cameraName>
      <imageTopicName>image_raw</imageTopicName>
      <cameraInfoTopicName>camera_info</cameraInfoTopicName>
    </plugin>
  </gazebo>

  <joint name="myrobot1/wheel_left_joint" type="continuous">
    <parent link="myrobot1/base_link"/>
    <child link="myrobot1wheel_left_link"/>
    <origin xyz="0.0 0.08 0.023" rpy="-1.57 0 0"/>
    <axis xyz="0 0 1"/>
  </joint>

  <link name="myrobot1/wheel_left_link">
    <visual>
      <origin xyz="0 0 0" rpy="1.57 0 0"/>
      <geometry>
        <mesh filename="package://turtlebot3_gazebo/models/turtlebot3_common/meshes/tire.dae" scale="0.001 0.001 0.001"/>
      </geometry>
      <material name="dark"/>
    </visual>

    <collision>
      <origin xyz="0 0 0" rpy="0 0 0"/>
      <geometry>
        <cylinder length="0.018" radius="0.033"/>
      </geometry>
    </collision>

    <inertial>
      <origin xyz="0 0 0" />
      <mass value="2.8498940e-02" />
      <inertia ixx="1.1175580e-05" ixy="-4.2369783e-11" ixz="-5.9381719e-09" iyy="1.1192413e-05" iyz="-1.4400107e-11" izz="2.0712558e-05" />
    </inertial>
  </link>

  <joint name="myrobot1/wheel_right_joint" type="continuous">
    <parent link="myrobot1/base_link"/>
    <child link="myrobot1wheel_right_link"/>
    <origin xyz="0.0 -0.080 0.023" rpy="-1.57 0 0"/>
    <axis xyz="0 0 1"/>
  </joint>

  <link name="myrobot1/wheel_right_link">
    <visual>
      <origin xyz="0 0 0" rpy="1.57 0 0"/>
      <geometry>
        <mesh filename="package://turtlebot3_gazebo/models/turtlebot3_common/meshes/tire.dae" scale="0.001 0.001 0.001"/>
      </geometry>
      <material name="dark"/>
    </visual>

    <collision>
      <origin xyz="0 0 0" rpy="0 0 0"/>
      <geometry>
        <cylinder length="0.018" radius="0.033"/>
      </geometry>
    </collision>

    <inertial>
      <origin xyz="0 0 0" />
      <mass value="2.8498940e-02" />
      <inertia ixx="1.1175580e-05" ixy="-4.2369783e-11" ixz="-5.9381719e-09" iyy="1.1192413e-05" iyz="-1.4400107e-11" izz="2.0712558e-05" />
    </inertial>
  </link>

  <joint name="myrobot1/caster_back_joint" type="fixed">
    <parent link="myrobot1/base_link"/>
    <child link="myrobot1caster_back_link"/>
    <origin xyz="-0.081 0 -0.004" rpy="-1.57 0 0"/>
  </joint>

  <link name="myrobot1/caster_back_link">
    <collision>
      <origin xyz="0 0.001 0" rpy="0 0 0"/>
      <geometry>
        <box size="0.030 0.009 0.020"/>
      </geometry>
    </collision>

    <inertial>
      <origin xyz="0 0 0" />
      <mass value="0.005" />
      <inertia ixx="0.001" ixy="0.0" ixz="0.0" iyy="0.001" iyz="0.0" izz="0.001" />
    </inertial>
  </link>

  <joint name="myrobot1/imu_joint" type="fixed">
    <parent link="myrobot1/base_link"/>
    <child link="myrobot1imu_link"/>
    <origin xyz="-0.032 0 0.068" rpy="0 0 0"/>
  </joint>

  <link name="myrobot1/imu_link"/>

  <joint name="myrobot1/scan_joint" type="fixed">
    <parent link="myrobot1/base_link"/>
    <child link="myrobot1base_scan"/>
    <origin xyz="-0.032 0 0.172" rpy="0 0 0"/>
  </joint>

  <link name="myrobot1/base_scan">
    <visual>
      <origin xyz="0 0 0.0" rpy="0 0 0"/>
      <geometry>
        <mesh filename="package://turtlebot3_gazebo/models/turtlebot3_common/meshes/lds.dae" scale="0.001 0.001 0.001"/>
      </geometry>
      <material name="dark"/>
    </visual>

    <collision>
      <origin xyz="0.015 0 -0.0065" rpy="0 0 0"/>
      <geometry>
        <cylinder length="0.0315" radius="0.055"/>
      </geometry>
    </collision>

    <inertial>
      <mass value="0.114" />
      <origin xyz="0 0 0" />
      <inertia ixx="0.001" ixy="0.0" ixz="0.0" iyy="0.001" iyz="0.0" izz="0.001" />
    </inertial>
  </link>

</robot>